Workbook
Name ActionStatusList: Lookups!$E$1:$E$5
Name BuisnessUnitList: Lookups!$D$1:$D$8
Name CategoryList: Lookups!$A$1:$A$7
Name ControlStrengthList: Lookups!$C$1:$C$4
Name PriorityList: Lookups!$F$1:$F$5
Name RiskStatusList: Lookups!$B$1:$B$6
Name Slicer_Status: #N/A
Name tblCategory: Lookups!$A$2:$A$7
Name tblRisk_Status: Lookups!$B$2:$B$6

Sheet Lookups
A1: Category | B1: Risk_Status | C1: Control_Strength | D1: Buisness_Unit | E1: Action Status | F1: Priority | G1: Risk_Source
A2: Operational | B2: Risk_Status | C2: Weak | D2: GO Ops | E2: Not Started | F2: Low | G2: Workshop
A3: IT | B3: New | C3: Moderate | D3: Bus Ops | E3: In Progress | F3: Medium | G3: Ops Meeting
A4: Safety | B4: In Review | C4: Strong | D4: Capital Projects | E4: Done | F4: High | G4: Audit
A5: Finance | B5: Active | D5: Corp Services | E5: Blocked | F5: Critical | G5: Incident
A6: Projects | B6: Closed | D6: Customer Experience
A7: Reputation | D7: Stations/Facillities
D8: Office of CRO

Sheet Risk_Register
A1: Risk_ID | B1: Title | C1: Category | D1: Buisness_Unit | E1: Owner | F1: Date_Identified | G1: Status | H1: Likelihood_Inherent | I1: Impact_Inherent | J1: Score_Inherent | K1: Control_Strength | L1: Likelihood_Residual | M1: Impact_residual | N1: Score_residual | O1: Appetite_alignment | P1: Last_review_date | Q1: Next_review_date | R1: Days_Open | S1: Is_Overdue_review | T1: Risk_Source | U1: Key_Controls | V1: MItigation_Summary
A2: RSK-2025-0001 | B2: Service Disruption due to Weather | C2: Operational | D2: Bus Ops | E2: Customer Communications Manager | F2: 45986 | G2: Closed | H2: 4 | I2: 2 | J2: =tblRisks[[#This Row],[Likelihood_Inherent]]*tblRisks[[#This Row],[Impact_Inherent]] -> 8 | K2: Weak | L2: 4 | M2: 1 | N2: =tblRisks[[#This Row],[Likelihood_Residual]]*tblRisks[[#This Row],[Impact_residual]] -> 4 | O2: =IF(tblRisks[[#This Row],[Score_residual]]>=15,"Outside",IF(tblRisks[[#This Row],[Score_residual]]>=10,"Borderline","Within")) -> Within | P2: 45988 | Q2: 45993 | R2: =ABS(tblRisks[[#This Row],[Last_review_date]]-tblRisks[[#This Row],[Date_Identified]] ) -> 2 | S2: =AND(tblRisks[[#This Row],[Status]]<>"Closed",tblRisks[[#This Row],[Next_review_date]]<TODAY()) -> FALSE | T2: Ops Meeting | U2: Weather monitoring; service recovery procedures | V2: Improve severe weather response and ensure adequate resource coverage during storms.
A3: RSK-2025-0002 | B3: Cybersecurity Vulnerabilities | C3: IT | D3: Corp Services | E3: Cybersecurity Manager | F3: 45986 | G3: Closed | H3: 3 | I3: 5 | J3: =tblRisks[[#This Row],[Likelihood_Inherent]]*tblRisks[[#This Row],[Impact_Inherent]] -> 15 | K3: Strong | L3: 2 | M3: 2 | N3: =tblRisks[[#This Row],[Likelihood_Residual]]*tblRisks[[#This Row],[Impact_residual]] -> 4 | O3: =IF(tblRisks[[#This Row],[Score_residual]]>=15,"Outside",IF(tblRisks[[#This Row],[Score_residual]]>=10,"Borderline","Within")) -> Within | P3: 45989 | Q3: 45993 | R3: =ABS(tblRisks[[#This Row],[Last_review_date]]-tblRisks[[#This Row],[Date_Identified]] ) -> 3 | S3: =AND(tblRisks[[#This Row],[Status]]<>"Closed",tblRisks[[#This Row],[Next_review_date]]<TODAY()) -> FALSE | T3: Audit | U3: MFA; vulnerability scanning; security monitoring | V3: Address critical vulnerabilities and strengthen security monitoring and evaluate management timelines.
A4: RSK-2025-0003 | B4: Equipment failure limits facility accessibility | C4: Reputation | D4: Customer Experience | E4: Accessibility Program Manager | F4: 45987 | G4: Closed | H4: 1 | I4: 4 | J4: =tblRisks[[#This Row],[Likelihood_Inherent]]*tblRisks[[#This Row],[Impact_Inherent]] -> 4 | K4: Moderate | L4: 3 | M4: 2 | N4: =tblRisks[[#This Row],[Likelihood_Residual]]*tblRisks[[#This Row],[Impact_residual]] -> 6 | O4: =IF(tblRisks[[#This Row],[Score_residual]]>=15,"Outside",IF(tblRisks[[#This Row],[Score_residual]]>=10,"Borderline","Within")) -> Within | P4: 45996 | Q4: 45994 | R4: =ABS(tblRisks[[#This Row],[Last_review_date]]-tblRisks[[#This Row],[Date_Identified]] ) -> 9 | S4: =AND(tblRisks[[#This Row],[Status]]<>"Closed",tblRisks[[#This Row],[Next_review_date]]<TODAY()) -> FALSE | T4: Incident | U4: Preventative maintenance; vendor escalation process | V4: Prioritize accessibility equipment repairs and improve vendor response time tracking.
A5: RSK-2025-0004 | B5: Service Disruption due to Weather | C5: Operational | D5: Stations/Facillities | E5: Supervisor, Stations & Facilities | F5: 45989 | G5: Closed | H5: 4 | I5: 2 | J5: =tblRisks[[#This Row],[Likelihood_Inherent]]*tblRisks[[#This Row],[Impact_Inherent]] -> 8 | K5: Weak | L5: 1 | M5: 1 | N5: =tblRisks[[#This Row],[Likelihood_Residual]]*tblRisks[[#This Row],[Impact_residual]] -> 1 | O5: =IF(tblRisks[[#This Row],[Score_residual]]>=15,"Outside",IF(tblRisks[[#This Row],[Score_residual]]>=10,"Borderline","Within")) -> Within | P5: 45993 | Q5: 45996 | R5: =ABS(tblRisks[[#This Row],[Last_review_date]]-tblRisks[[#This Row],[Date_Identified]] ) -> 4 | S5: =AND(tblRisks[[#This Row],[Status]]<>"Closed",tblRisks[[#This Row],[Next_review_date]]<TODAY()) -> FALSE | T5: Ops Meeting | U5: Winter maintenance; incident response procedures | V5: Strengthen winter readiness and ensure station teams follow standardized disruption protocols.
A6: RSK-2025-0005 | B6: Slip hazard due to Winter Condition | C6: Safety | D6: Stations/Facillities | E6: Stations Maintenance Lead | F6: 45989 | G6: Closed | H6: 3 | I6: 3 | J6: =tblRisks[[#This Row],[Likelihood_Inherent]]*tblRisks[[#This Row],[Impact_Inherent]] -> 9 | K6: Weak | L6: 1 | M6: 1 | N6: =tblRisks[[#This Row],[Likelihood_Residual]]*tblRisks[[#This Row],[Impact_residual]] -> 1 | O6: =IF(tblRisks[[#This Row],[Score_residual]]>=15,"Outside",IF(tblRisks[[#This Row],[Score_residual]]>=10,"Borderline","Within")) -> Within | P6: 45993 | Q6: 45993 | R6: =ABS(tblRisks[[#This Row],[Last_review_date]]-tblRisks[[#This Row],[Date_Identified]] ) -> 4 | S6: =AND(tblRisks[[#This Row],[Status]]<>"Closed",tblRisks[[#This Row],[Next_review_date]]<TODAY()) -> FALSE | T6: Incident | U6: Salt/grit procedures; safety inspections | V6: Increase winter inspections and standardize hazard reporting and follow-up.
A7: RSK-2025-0006 | B7: Maintenance Request Delay | C7: Operational | D7: Stations/Facillities | E7: Supervisor, Stations & Facilities | F7: 45992 | G7: Closed | H7: 3 | I7: 3 | J7: =tblRisks[[#This Row],[Likelihood_Inherent]]*tblRisks[[#This Row],[Impact_Inherent]] -> 9 | K7: Moderate | L7: 2 | M7: 2 | N7: =tblRisks[[#This Row],[Likelihood_Residual]]*tblRisks[[#This Row],[Impact_residual]] -> 4 | O7: =IF(tblRisks[[#This Row],[Score_residual]]>=15,"Outside",IF(tblRisks[[#This Row],[Score_residual]]>=10,"Borderline","Within")) -> Within | P7: 45995 | Q7: 45995 | R7: =ABS(tblRisks[[#This Row],[Last_review_date]]-tblRisks[[#This Row],[Date_Identified]] ) -> 3 | S7: =AND(tblRisks[[#This Row],[Status]]<>"Closed",tblRisks[[#This Row],[Next_review_date]]<TODAY()) -> FALSE | T7: Staff Report | U7: Work order process; triage procedures | V7: Prioritize work orders more effectively and monitor maintenance request response time KPIs.
A8: RSK-2025-0007 | B8: Systems Integration Delays Resulting in Duplicate Requests | C8: IT | D8: Corp Services | E8: IT Operations Lead | F8: 45993 | G8: Closed | H8: 2 | I8: 2 | J8: =tblRisks[[#This Row],[Likelihood_Inherent]]*tblRisks[[#This Row],[Impact_Inherent]] -> 4 | K8: Moderate | L8: 1 | M8: 1 | N8: =tblRisks[[#This Row],[Likelihood_Residual]]*tblRisks[[#This Row],[Impact_residual]] -> 1 | O8: =IF(tblRisks[[#This Row],[Score_residual]]>=15,"Outside",IF(tblRisks[[#This Row],[Score_residual]]>=10,"Borderline","Within")) -> Within | P8: 46000 | Q8: 46000 | R8: =ABS(tblRisks[[#This Row],[Last_review_date]]-tblRisks[[#This Row],[Date_Identified]] ) -> 7 | S8: =AND(tblRisks[[#This Row],[Status]]<>"Closed",tblRisks[[#This Row],[Next_review_date]]<TODAY()) -> FALSE | T8: Project Review | U8: Change management; system testing procedures | V8: Enhance integration testing and put restrictions in place to cut down on the number of duplicate requests.
A9: RSK-2026-0008 | B9: Stakeholder Dissatisfaction Following Project Delays | C9: Finance | D9: Office of CRO | E9: Senior Manager, Risk Advisory | F9: 46065 | G9: In Review | H9: 2 | I9: 5 | J9: =tblRisks[[#This Row],[Likelihood_Inherent]]*tblRisks[[#This Row],[Impact_Inherent]] -> 10 | K9: Moderate | L9: 4 | M9: 4 | N9: =tblRisks[[#This Row],[Likelihood_Residual]]*tblRisks[[#This Row],[Impact_residual]] -> 16 | O9: =IF(tblRisks[[#This Row],[Score_residual]]>=15,"Outside",IF(tblRisks[[#This Row],[Score_residual]]>=10,"Borderline","Within")) -> Outside | P9: 46065 | Q9: 46072 | R9: =ABS(tblRisks[[#This Row],[Last_review_date]]-tblRisks[[#This Row],[Date_Identified]] ) -> 0 | S9: =AND(tblRisks[[#This Row],[Status]]<>"Closed",tblRisks[[#This Row],[Next_review_date]]<TODAY()) -> FALSE | T9: Project Review | U9: Project governance; schedule oversight | V9: Improve stakeholder communications and implement escalation triggers for project delay impacts.
A10: RSK-2025-0009 | B10: Service Delays leading to Customer Dissatisfaction | C10: Reputation | D10: Customer Experience | E10: Customer Communications Manager | F10: 45996 | G10: Closed | H10: 3 | I10: 3 | J10: =tblRisks[[#This Row],[Likelihood_Inherent]]*tblRisks[[#This Row],[Impact_Inherent]] -> 9 | K10: Weak | L10: 1 | M10: 1 | N10: =tblRisks[[#This Row],[Likelihood_Residual]]*tblRisks[[#This Row],[Impact_residual]] -> 1 | O10: =IF(tblRisks[[#This Row],[Score_residual]]>=15,"Outside",IF(tblRisks[[#This Row],[Score_residual]]>=10,"Borderline","Within")) -> Within | P10: 46003 | Q10: 46003 | R10: =ABS(tblRisks[[#This Row],[Last_review_date]]-tblRisks[[#This Row],[Date_Identified]] ) -> 7 | S10: =AND(tblRisks[[#This Row],[Status]]<>"Closed",tblRisks[[#This Row],[Next_review_date]]<TODAY()) -> FALSE | T10: Ops Meeting | U10: Service alerts; operational recovery protocols | V10: Improve disruption communications and improve consistency of service recovery.
A11: RSK-2026-0010 | B11: Scope Creep leads to Stakeholder Concern | C11: Finance | D11: Office of CRO | E11: Senior Manager, Risk Advisory | F11: 46029 | G11: In Review | H11: 3 | I11: 5 | J11: =tblRisks[[#This Row],[Likelihood_Inherent]]*tblRisks[[#This Row],[Impact_Inherent]] -> 15 | K11: Moderate | L11: 4 | M11: 3 | N11: =tblRisks[[#This Row],[Likelihood_Residual]]*tblRisks[[#This Row],[Impact_residual]] -> 12 | O11: =IF(tblRisks[[#This Row],[Score_residual]]>=15,"Outside",IF(tblRisks[[#This Row],[Score_residual]]>=10,"Borderline","Within")) -> Borderline | P11: 46064 | Q11: 46071 | R11: =ABS(tblRisks[[#This Row],[Last_review_date]]-tblRisks[[#This Row],[Date_Identified]] ) -> 35 | S11: =AND(tblRisks[[#This Row],[Status]]<>"Closed",tblRisks[[#This Row],[Next_review_date]]<TODAY()) -> FALSE | T11: Project Review | U11: Stakeholder governance; change control process | V11: Improve scope management and ensure stakeholder alignment through standardized change control.
A12: RSK-2025-0011 | B12: Equipment Failure causes Service Disruptions | C12: Safety | D12: Stations/Facillities | E12: Safety Program Lead | F12: 46002 | G12: Closed | H12: 2 | I12: 4 | J12: =tblRisks[[#This Row],[Likelihood_Inherent]]*tblRisks[[#This Row],[Impact_Inherent]] -> 8 | K12: Moderate | L12: 3 | M12: 2 | N12: =tblRisks[[#This Row],[Likelihood_Residual]]*tblRisks[[#This Row],[Impact_residual]] -> 6 | O12: =IF(tblRisks[[#This Row],[Score_residual]]>=15,"Outside",IF(tblRisks[[#This Row],[Score_residual]]>=10,"Borderline","Within")) -> Within | P12: 46009 | Q12: 46009 | R12: =ABS(tblRisks[[#This Row],[Last_review_date]]-tblRisks[[#This Row],[Date_Identified]] ) -> 7 | S12: =AND(tblRisks[[#This Row],[Status]]<>"Closed",tblRisks[[#This Row],[Next_review_date]]<TODAY()) -> FALSE | T12: Incident | U12: Preventative maintenance; safety checks | V12: Reduce equipment failures through enhanced preventative maintenance tracking and recurring issue analysis.
A13: RSK-2026-0012 | B13: Data Access Issues Following Staff Turnover | C13: IT | D13: Corp Services | E13: IT Operations Lead | F13: 46062 | G13: In Review | H13: 2 | I13: 4 | J13: =tblRisks[[#This Row],[Likelihood_Inherent]]*tblRisks[[#This Row],[Impact_Inherent]] -> 8 | K13: Strong | L13: 2 | M13: 3 | N13: =tblRisks[[#This Row],[Likelihood_Residual]]*tblRisks[[#This Row],[Impact_residual]] -> 6 | O13: =IF(tblRisks[[#This Row],[Score_residual]]>=15,"Outside",IF(tblRisks[[#This Row],[Score_residual]]>=10,"Borderline","Within")) -> Within | P13: 46062 | Q13: 46069 | R13: =ABS(tblRisks[[#This Row],[Last_review_date]]-tblRisks[[#This Row],[Date_Identified]] ) -> 0 | S13: =AND(tblRisks[[#This Row],[Status]]<>"Closed",tblRisks[[#This Row],[Next_review_date]]<TODAY()) -> FALSE | T13: Incident | U13: Access management process; onboarding/offboarding controls | V13: Improve access provisioning controls and ensure timely access removal following staff turnover.
... A28: RSK-2026-0027 | B28: Trespassing Incident | C28: Safety | D28: GO Ops | E28: Safety Program Lead | F28: 46041 | G28: In Review | H28: 1 | I28: 4 | J28: =tblRisks[[#This Row],[Likelihood_Inherent]]*tblRisks[[#This Row],[Impact_Inherent]] -> 4 | K28: Weak | L28: 1 | M28: 1 | N28: =tblRisks[[#This Row],[Likelihood_Residual]]*tblRisks[[#This Row],[Impact_residual]] -> 1 | O28: =IF(tblRisks[[#This Row],[Score_residual]]>=15,"Outside",IF(tblRisks[[#This Row],[Score_residual]]>=10,"Borderline","Within")) -> Within | P28: 46066 | Q28: 46069 | R28: =ABS(tblRisks[[#This Row],[Last_review_date]]-tblRisks[[#This Row],[Date_Identified]] ) -> 25 | S28: =AND(tblRisks[[#This Row],[Status]]<>"Closed",tblRisks[[#This Row],[Next_review_date]]<TODAY()) -> FALSE | T28: Incident | U28: Safety patrols; incident reporting procedures | V28: Strengthen trespassing prevention and improve reporting consistency for follow-up.

Sheet Action_Tracker
A1: Action_ID | B1: Risk_ID | C1: Action_Title | D1: Owner | E1: Due_Date | F1: Status | G1: Priority | H1: Percent_Complete | I1: Is_Overdue | J1: Days_Overdue | K1: Last_Updated | L1: Notes
A2: {=SUBSTITUTE(INDEX(tblRisks[Risk_ID],ROW()-1),"RSK","ACT")} -> ACT-2025-0001 | B2: RSK-2025-0001 | C2: Service Disruption due to Weather | D2: Customer Communications Manager | E2: =IFERROR(VLOOKUP(tblActions[[#This Row],[Risk_ID]], tblRisks[], MATCH("Next_review_date", tblRisks[#Headers], 0), FALSE), "") -> 45993 | F2: Closed | G2: Low | H2: 1 | I2: =IF(tblActions[[#This Row],[Status]]="Closed",FALSE,IF(tblActions[[#This Row],[Due_Date]]="",FALSE,tblActions[[#This Row],[Due_Date]]<TODAY())) -> FALSE | J2: =IF(tblActions[[#This Row],[Status]]="Closed","",IF(tblActions[[#This Row],[Due_Date]]="","",MAX(0,TODAY()-tblActions[[#This Row],[Due_Date]])))
A3: {=SUBSTITUTE(INDEX(tblRisks[Risk_ID],ROW()-1),"RSK","ACT")} -> ACT-2025-0002 | B3: RSK-2025-0002 | C3: Cybersecurity Vulnerabilities | D3: Cybersecurity Manager | E3: =IFERROR(VLOOKUP(tblActions[[#This Row],[Risk_ID]], tblRisks[], MATCH("Next_review_date", tblRisks[#Headers], 0), FALSE), "") -> 45993 | F3: Closed | G3: High | H3: 1 | I3: =IF(tblActions[[#This Row],[Status]]="Closed",FALSE,IF(tblActions[[#This Row],[Due_Date]]="",FALSE,tblActions[[#This Row],[Due_Date]]<TODAY())) -> FALSE | J3: =IF(tblActions[[#This Row],[Status]]="Closed","",IF(tblActions[[#This Row],[Due_Date]]="","",MAX(0,TODAY()-tblActions[[#This Row],[Due_Date]])))
A4: {=SUBSTITUTE(INDEX(tblRisks[Risk_ID],ROW()-1),"RSK","ACT")} -> ACT-2025-0003 | B4: RSK-2025-0003 | C4: Equipment failure limits facility accessibility | D4: Accessibility Program Manager | E4: =IFERROR(VLOOKUP(tblActions[[#This Row],[Risk_ID]], tblRisks[], MATCH("Next_review_date", tblRisks[#Headers], 0), FALSE), "") -> 45994 | F4: Closed | G4: High | H4: 1 | I4: =IF(tblActions[[#This Row],[Status]]="Closed",FALSE,IF(tblActions[[#This Row],[Due_Date]]="",FALSE,tblActions[[#This Row],[Due_Date]]<TODAY())) -> FALSE | J4: =IF(tblActions[[#This Row],[Status]]="Closed","",IF(tblActions[[#This Row],[Due_Date]]="","",MAX(0,TODAY()-tblActions[[#This Row],[Due_Date]])))
A5: {=SUBSTITUTE(INDEX(tblRisks[Risk_ID],ROW()-1),"RSK","ACT")} -> ACT-2025-0004 | B5: RSK-2025-0004 | C5: Service Disruption due to Weather | D5: Supervisor, Stations & Facilities | E5: =IFERROR(VLOOKUP(tblActions[[#This Row],[Risk_ID]], tblRisks[], MATCH("Next_review_date", tblRisks[#Headers], 0), FALSE), "") -> 45996 | F5: Closed | G5: Low | H5: 1 | I5: =IF(tblActions[[#This Row],[Status]]="Closed",FALSE,IF(tblActions[[#This Row],[Due_Date]]="",FALSE,tblActions[[#This Row],[Due_Date]]<TODAY())) -> FALSE | J5: =IF(tblActions[[#This Row],[Status]]="Closed","",IF(tblActions[[#This Row],[Due_Date]]="","",MAX(0,TODAY()-tblActions[[#This Row],[Due_Date]])))
A6: {=SUBSTITUTE(INDEX(tblRisks[Risk_ID],ROW()-1),"RSK","ACT")} -> ACT-2025-0005 | B6: RSK-2025-0005 | C6: Slip hazard due to Winter Condition | D6: Stations Maintenance Lead | E6: =IFERROR(VLOOKUP(tblActions[[#This Row],[Risk_ID]], tblRisks[], MATCH("Next_review_date", tblRisks[#Headers], 0), FALSE), "") -> 45993 | F6: Closed | G6: Medium | H6: 1 | I6: =IF(tblActions[[#This Row],[Status]]="Closed",FALSE,IF(tblActions[[#This Row],[Due_Date]]="",FALSE,tblActions[[#This Row],[Due_Date]]<TODAY())) -> FALSE | J6: =IF(tblActions[[#This Row],[Status]]="Closed","",IF(tblActions[[#This Row],[Due_Date]]="","",MAX(0,TODAY()-tblActions[[#This Row],[Due_Date]])))
A7: {=SUBSTITUTE(INDEX(tblRisks[Risk_ID],ROW()-1),"RSK","ACT")} -> ACT-2025-0006 | B7: RSK-2025-0006 | C7: Maintenance Request Delay | D7: Supervisor, Stations & Facilities | E7: =IFERROR(VLOOKUP(tblActions[[#This Row],[Risk_ID]], tblRisks[], MATCH("Next_review_date", tblRisks[#Headers], 0), FALSE), "") -> 45995 | F7: Closed | G7: Medium | H7: 1 | I7: =IF(tblActions[[#This Row],[Status]]="Closed",FALSE,IF(tblActions[[#This Row],[Due_Date]]="",FALSE,tblActions[[#This Row],[Due_Date]]<TODAY())) -> FALSE | J7: =IF(tblActions[[#This Row],[Status]]="Closed","",IF(tblActions[[#This Row],[Due_Date]]="","",MAX(0,TODAY()-tblActions[[#This Row],[Due_Date]])))
A8: {=SUBSTITUTE(INDEX(tblRisks[Risk_ID],ROW()-1),"RSK","ACT")} -> ACT-2025-0007 | B8: RSK-2025-0007 | C8: Systems Integration Delays Resulting in Duplicate Requests | D8: IT Operations Lead | E8: =IFERROR(VLOOKUP(tblActions[[#This Row],[Risk_ID]], tblRisks[], MATCH("Next_review_date", tblRisks[#Headers], 0), FALSE), "") -> 46000 | F8: Closed | G8: Low | H8: 1 | I8: =IF(tblActions[[#This Row],[Status]]="Closed",FALSE,IF(tblActions[[#This Row],[Due_Date]]="",FALSE,tblActions[[#This Row],[Due_Date]]<TODAY())) -> FALSE | J8: =IF(tblActions[[#This Row],[Status]]="Closed","",IF(tblActions[[#This Row],[Due_Date]]="","",MAX(0,TODAY()-tblActions[[#This Row],[Due_Date]])))
A9: {=SUBSTITUTE(INDEX(tblRisks[Risk_ID],ROW()-1),"RSK","ACT")} -> ACT-2026-0008 | B9: RSK-2026-0008 | C9: Budget constraints effecting LRT timeline | D9: Senior Manager, Risk Advisory | E9: =IFERROR(VLOOKUP(tblActions[[#This Row],[Risk_ID]], tblRisks[], MATCH("Next_review_date", tblRisks[#Headers], 0), FALSE), "") -> 46072 | F9: Active | G9: High | H9: 0.75 | I9: =IF(tblActions[[#This Row],[Status]]="Closed",FALSE,IF(tblActions[[#This Row],[Due_Date]]="",FALSE,tblActions[[#This Row],[Due_Date]]<TODAY())) -> FALSE | J9: =IF(tblActions[[#This Row],[Status]]="Closed","",IF(tblActions[[#This Row],[Due_Date]]="","",MAX(0,TODAY()-tblActions[[#This Row],[Due_Date]]))) -> 0
A10: {=SUBSTITUTE(INDEX(tblRisks[Risk_ID],ROW()-1),"RSK","ACT")} -> ACT-2025-0009 | B10: RSK-2025-0009 | C10: Service Delays leading to Customer Dissatisfaction | D10: Customer Communications Manager | E10: =IFERROR(VLOOKUP(tblActions[[#This Row],[Risk_ID]], tblRisks[], MATCH("Next_review_date", tblRisks[#Headers], 0), FALSE), "") -> 46003 | F10: Closed | G10: Low | H10: 1 | I10: =IF(tblActions[[#This Row],[Status]]="Closed",FALSE,IF(tblActions[[#This Row],[Due_Date]]="",FALSE,tblActions[[#This Row],[Due_Date]]<TODAY())) -> FALSE | J10: =IF(tblActions[[#This Row],[Status]]="Closed","",IF(tblActions[[#This Row],[Due_Date]]="","",MAX(0,TODAY()-tblActions[[#This Row],[Due_Date]])))
A11: {=SUBSTITUTE(INDEX(tblRisks[Risk_ID],ROW()-1),"RSK","ACT")} -> ACT-2026-0010 | B11: RSK-2026-0010 | C11: Construction Delays impacting Accessibility Projects | D11: Accessibility Program Manager | E11: =IFERROR(VLOOKUP(tblActions[[#This Row],[Risk_ID]], tblRisks[], MATCH("Next_review_date", tblRisks[#Headers], 0), FALSE), "") -> 46071 | F11: In Review | G11: High | H11: 0.5 | I11: =IF(tblActions[[#This Row],[Status]]="Closed",FALSE,IF(tblActions[[#This Row],[Due_Date]]="",FALSE,tblActions[[#This Row],[Due_Date]]<TODAY())) -> FALSE | J11: =IF(tblActions[[#This Row],[Status]]="Closed","",IF(tblActions[[#This Row],[Due_Date]]="","",MAX(0,TODAY()-tblActions[[#This Row],[Due_Date]]))) -> 0
A12: {=SUBSTITUTE(INDEX(tblRisks[Risk_ID],ROW()-1),"RSK","ACT")} -> ACT-2025-0011 | B12: RSK-2025-0011 | C12: Equipment Failure causes Service Disruptions | D12: Safety Program Lead | E12: =IFERROR(VLOOKUP(tblActions[[#This Row],[Risk_ID]], tblRisks[], MATCH("Next_review_date", tblRisks[#Headers], 0), FALSE), "") -> 46009 | F12: Closed | G12: High | H12: 1 | I12: =IF(tblActions[[#This Row],[Status]]="Closed",FALSE,IF(tblActions[[#This Row],[Due_Date]]="",FALSE,tblActions[[#This Row],[Due_Date]]<TODAY())) -> FALSE | J12: =IF(tblActions[[#This Row],[Status]]="Closed","",IF(tblActions[[#This Row],[Due_Date]]="","",MAX(0,TODAY()-tblActions[[#This Row],[Due_Date]])))
A13: {=SUBSTITUTE(INDEX(tblRisks[Risk_ID],ROW()-1),"RSK","ACT")} -> ACT-2026-0012 | B13: RSK-2026-0012 | C13: Delays in Project Progression due to insufficient Documentation | D13: Project Controls Manager | E13: =IFERROR(VLOOKUP(tblActions[[#This Row],[Risk_ID]], tblRisks[], MATCH("Next_review_date", tblRisks[#Headers], 0), FALSE), "") -> 46069 | F13: Active | G13: High | H13: 0.75 | I13: =IF(tblActions[[#This Row],[Status]]="Closed",FALSE,IF(tblActions[[#This Row],[Due_Date]]="",FALSE,tblActions[[#This Row],[Due_Date]]<TODAY())) -> FALSE | J13: =IF(tblActions[[#This Row],[Status]]="Closed","",IF(tblActions[[#This Row],[Due_Date]]="","",MAX(0,TODAY()-tblActions[[#This Row],[Due_Date]]))) -> 0
... A16: {=SUBSTITUTE(INDEX(tblRisks[Risk_ID],ROW()-1),"RSK","ACT")} -> ACT-2026-0015 | B16: RSK-2026-0015 | C16: Communications Delays leading to Customer Dissatisfaction | D16: Customer Communications Manager | E16: =IFERROR(VLOOKUP(tblActions[[#This Row],[Risk_ID]], tblRisks[], MATCH("Next_review_date", tblRisks[#Headers], 0), FALSE), "") -> 46034 | F16: Closed | G16: Low | H16: 1 | I16: =IF(tblActions[[#This Row],[Status]]="Closed",FALSE,IF(tblActions[[#This Row],[Due_Date]]="",FALSE,tblActions[[#This Row],[Due_Date]]<TODAY())) -> FALSE | J16: =IF(tblActions[[#This Row],[Status]]="Closed","",IF(tblActions[[#This Row],[Due_Date]]="","",MAX(0,TODAY()-tblActions[[#This Row],[Due_Date]])))
A17: {=SUBSTITUTE(INDEX(tblRisks[Risk_ID],ROW()-1),"RSK","ACT")} -> ACT-2025-0016 | B17: RSK-2026-0016 | C17: Scope Creep leads to Stakeholder Concern | D17: Senior Manager, Risk Advisory | E17: =IFERROR(VLOOKUP(tblActions[[#This Row],[Risk_ID]], tblRisks[], MATCH("Next_review_date", tblRisks[#Headers], 0), FALSE), "") | F17: In Review | G17: Critical | H17: 0.5 | I17: =IF(tblActions[[#This Row],[Status]]="Closed",FALSE,IF(tblActions[[#This Row],[Due_Date]]="",FALSE,tblActions[[#This Row],[Due_Date]]<TODAY())) -> FALSE | J17: =IF(tblActions[[#This Row],[Status]]="Closed","",IF(tblActions[[#This Row],[Due_Date]]="","",MAX(0,TODAY()-tblActions[[#This Row],[Due_Date]]))) | K17: 46066 | L17: CRO meeting scheduled
A18: {=SUBSTITUTE(INDEX(tblRisks[Risk_ID],ROW()-1),"RSK","ACT")} -> ACT-2026-0017 | B18: RSK-2026-0017 | C18: Media Scrutiny Following Equipment Failure | D18: Customer Communications Manager | E18: =IFERROR(VLOOKUP(tblActions[[#This Row],[Risk_ID]], tblRisks[], MATCH("Next_review_date", tblRisks[#Headers], 0), FALSE), "") -> 46038 | F18: Closed | G18: High | H18: 1 | I18: =IF(tblActions[[#This Row],[Status]]="Closed",FALSE,IF(tblActions[[#This Row],[Due_Date]]="",FALSE,tblActions[[#This Row],[Due_Date]]<TODAY())) -> FALSE | J18: =IF(tblActions[[#This Row],[Status]]="Closed","",IF(tblActions[[#This Row],[Due_Date]]="","",MAX(0,TODAY()-tblActions[[#This Row],[Due_Date]])))
A19: {=SUBSTITUTE(INDEX(tblRisks[Risk_ID],ROW()-1),"RSK","ACT")} -> ACT-2026-0018 | B19: RSK-2026-0018 | C19: System Downtime leading to Delayed App Communications | D19: IT Operations Lead | E19: =IFERROR(VLOOKUP(tblActions[[#This Row],[Risk_ID]], tblRisks[], MATCH("Next_review_date", tblRisks[#Headers], 0), FALSE), "") -> 46041 | F19: Closed | G19: Low | H19: 1 | I19: =IF(tblActions[[#This Row],[Status]]="Closed",FALSE,IF(tblActions[[#This Row],[Due_Date]]="",FALSE,tblActions[[#This Row],[Due_Date]]<TODAY())) -> FALSE | J19: =IF(tblActions[[#This Row],[Status]]="Closed","",IF(tblActions[[#This Row],[Due_Date]]="","",MAX(0,TODAY()-tblActions[[#This Row],[Due_Date]])))
A20: {=SUBSTITUTE(INDEX(tblRisks[Risk_ID],ROW()-1),"RSK","ACT")} -> ACT-2026-0019 | B20: RSK-2026-0019 | C20: Budget Constraints Limiting Planned Facility Upgrades | D20: Senior Manager, Risk Advisory | E20: =IFERROR(VLOOKUP(tblActions[[#This Row],[Risk_ID]], tblRisks[], MATCH("Next_review_date", tblRisks[#Headers], 0), FALSE), "") -> 46041 | F20: Closed | G20: Low | H20: 1 | I20: =IF(tblActions[[#This Row],[Status]]="Closed",FALSE,IF(tblActions[[#This Row],[Due_Date]]="",FALSE,tblActions[[#This Row],[Due_Date]]<TODAY())) -> FALSE | J20: =IF(tblActions[[#This Row],[Status]]="Closed","",IF(tblActions[[#This Row],[Due_Date]]="","",MAX(0,TODAY()-tblActions[[#This Row],[Due_Date]])))
A21: {=SUBSTITUTE(INDEX(tblRisks[Risk_ID],ROW()-1),"RSK","ACT")} -> ACT-2026-0020 | B21: RSK-2026-0020 | C21: Station Closure due to Electrical Hazard | D21: Supervisor, Stations & Facilities | E21: =IFERROR(VLOOKUP(tblActions[[#This Row],[Risk_ID]], tblRisks[], MATCH("Next_review_date", tblRisks[#Headers], 0), FALSE), "") -> 46043 | F21: Closed | G21: Low | H21: 1 | I21: =IF(tblActions[[#This Row],[Status]]="Closed",FALSE,IF(tblActions[[#This Row],[Due_Date]]="",FALSE,tblActions[[#This Row],[Due_Date]]<TODAY())) -> FALSE | J21: =IF(tblActions[[#This Row],[Status]]="Closed","",IF(tblActions[[#This Row],[Due_Date]]="","",MAX(0,TODAY()-tblActions[[#This Row],[Due_Date]])))
A22: {=SUBSTITUTE(INDEX(tblRisks[Risk_ID],ROW()-1),"RSK","ACT")} -> ACT-2025-0021 | B22: RSK-2026-0021 | C22: Public Dissatisfaction Following Station Closure | D22: Customer Communications Manager | E22: =IFERROR(VLOOKUP(tblActions[[#This Row],[Risk_ID]], tblRisks[], MATCH("Next_review_date", tblRisks[#Headers], 0), FALSE), "") | F22: In Review | G22: Low | H22: 0.25 | I22: =IF(tblActions[[#This Row],[Status]]="Closed",FALSE,IF(tblActions[[#This Row],[Due_Date]]="",FALSE,tblActions[[#This Row],[Due_Date]]<TODAY())) -> FALSE | J22: =IF(tblActions[[#This Row],[Status]]="Closed","",IF(tblActions[[#This Row],[Due_Date]]="","",MAX(0,TODAY()-tblActions[[#This Row],[Due_Date]]))) | K22: 46066
A23: {=SUBSTITUTE(INDEX(tblRisks[Risk_ID],ROW()-1),"RSK","ACT")} -> ACT-2025-0022 | B23: RSK-2026-0022 | C23: Trespassing Incident | D23: Safety Program Lead | E23: =IFERROR(VLOOKUP(tblActions[[#This Row],[Risk_ID]], tblRisks[], MATCH("Next_review_date", tblRisks[#Headers], 0), FALSE), "") | F23: In Review | G23: Medium | H23: 0.25 | I23: =IF(tblActions[[#This Row],[Status]]="Closed",FALSE,IF(tblActions[[#This Row],[Due_Date]]="",FALSE,tblActions[[#This Row],[Due_Date]]<TODAY())) -> FALSE | J23: =IF(tblActions[[#This Row],[Status]]="Closed","",IF(tblActions[[#This Row],[Due_Date]]="","",MAX(0,TODAY()-tblActions[[#This Row],[Due_Date]]))) | K23: 46066
A24: {=SUBSTITUTE(INDEX(tblRisks[Risk_ID],ROW()-1),"RSK","ACT")} -> ACT-2026-0023 | B24: RSK-2026-0023 | C24: Customer Dissatisfaction due to Station Uncleanliness | D24: Supervisor, Stations & Facilities | E24: =IFERROR(VLOOKUP(tblActions[[#This Row],[Risk_ID]], tblRisks[], MATCH("Next_review_date", tblRisks[#Headers], 0), FALSE), "") -> 46071 | F24: Active | G24: Low | H24: 0.75 | I24: =IF(tblActions[[#This Row],[Status]]="Closed",FALSE,IF(tblActions[[#This Row],[Due_Date]]="",FALSE,tblActions[[#This Row],[Due_Date]]<TODAY())) -> FALSE | J24: =IF(tblActions[[#This Row],[Status]]="Closed","",IF(tblActions[[#This Row],[Due_Date]]="","",MAX(0,TODAY()-tblActions[[#This Row],[Due_Date]]))) -> 0 | K24: 46066
A25: {=SUBSTITUTE(INDEX(tblRisks[Risk_ID],ROW()-1),"RSK","ACT")} -> ACT-2026-0024 | B25: RSK-2026-0024 | C25: CCTV Outages Limiting Incident Response Capability | D25: Supervisor, Stations & Facilities | E25: =IFERROR(VLOOKUP(tblActions[[#This Row],[Risk_ID]], tblRisks[], MATCH("Next_review_date", tblRisks[#Headers], 0), FALSE), "") -> 46070 | F25: New | G25: High | H25: 0 | I25: =IF(tblActions[[#This Row],[Status]]="Closed",FALSE,IF(tblActions[[#This Row],[Due_Date]]="",FALSE,tblActions[[#This Row],[Due_Date]]<TODAY())) -> FALSE | J25: =IF(tblActions[[#This Row],[Status]]="Closed","",IF(tblActions[[#This Row],[Due_Date]]="","",MAX(0,TODAY()-tblActions[[#This Row],[Due_Date]]))) -> 0
A26: {=SUBSTITUTE(INDEX(tblRisks[Risk_ID],ROW()-1),"RSK","ACT")} -> ACT-2026-0025 | B26: RSK-2026-0025 | C26: Emergency Drill Inconsistency Across Sites | D26: Supervisor, Stations & Facilities | E26: =IFERROR(VLOOKUP(tblActions[[#This Row],[Risk_ID]], tblRisks[], MATCH("Next_review_date", tblRisks[#Headers], 0), FALSE), "") -> 46072 | F26: New | G26: High | H26: 0 | I26: =IF(tblActions[[#This Row],[Status]]="Closed",FALSE,IF(tblActions[[#This Row],[Due_Date]]="",FALSE,tblActions[[#This Row],[Due_Date]]<TODAY())) -> FALSE | J26: =IF(tblActions[[#This Row],[Status]]="Closed","",IF(tblActions[[#This Row],[Due_Date]]="","",MAX(0,TODAY()-tblActions[[#This Row],[Due_Date]]))) -> 0
A27: {=SUBSTITUTE(INDEX(tblRisks[Risk_ID],ROW()-1),"RSK","ACT")} -> ACT-2026-0026 | B27: RSK-2026-0026 | C27: Data Access Issues Following Staff Turnover | D27: IT Operations Lead | E27: =IFERROR(VLOOKUP(tblActions[[#This Row],[Risk_ID]], tblRisks[], MATCH("Next_review_date", tblRisks[#Headers], 0), FALSE), "") -> 46072 | F27: In Review | G27: High | H27: 0.25 | I27: =IF(tblActions[[#This Row],[Status]]="Closed",FALSE,IF(tblActions[[#This Row],[Due_Date]]="",FALSE,tblActions[[#This Row],[Due_Date]]<TODAY())) -> FALSE | J27: =IF(tblActions[[#This Row],[Status]]="Closed","",IF(tblActions[[#This Row],[Due_Date]]="","",MAX(0,TODAY()-tblActions[[#This Row],[Due_Date]]))) -> 0 | K27: 46066
A28: {=SUBSTITUTE(INDEX(tblRisks[Risk_ID],ROW()-1),"RSK","ACT")} -> ACT-2026-0027 | B28: RSK-2026-0027 | C28: Stakeholder Dissatisfaction Following Project Delays | D28: Senior Manager, Risk Advisory | E28: =IFERROR(VLOOKUP(tblActions[[#This Row],[Risk_ID]], tblRisks[], MATCH("Next_review_date", tblRisks[#Headers], 0), FALSE), "") -> 46069 | F28: In Review | G28: Critical | H28: 0.25 | I28: =IF(tblActions[[#This Row],[Status]]="Closed",FALSE,IF(tblActions[[#This Row],[Due_Date]]="",FALSE,tblActions[[#This Row],[Due_Date]]<TODAY())) -> FALSE | J28: =IF(tblActions[[#This Row],[Status]]="Closed","",IF(tblActions[[#This Row],[Due_Date]]="","",MAX(0,TODAY()-tblActions[[#This Row],[Due_Date]]))) -> 0 | K28: 46066
A29: ACT-2026-0101 | B29: RSK-2026-0008 | C29: Create revised cost forecast and identify top 3 funding gaps | D29: Senior Manager, Risk Advisory | E29: 46037 | F29: Active | G29: High | H29: 0 | I29: TRUE | J29: 32 | K29: 46037 | L29: Initial draft started, awaiting finance inputs
A30: ACT-2026-0102 | B30: RSK-2026-0010 | C30: Confirm revised construction schedule and update comms plan | D30: Accessibility Program Manager | E30: 46054 | F30: Active | G30: Medium | H30: 0.25 | I30: TRUE | J30: 15 | K30: 46054 | L30: Waiting on contractor confirmation
A31: ACT-2026-0103 | B31: RSK-2026-0012 | C31: Create documentation checklist and assign missing deliverables | D31: Project Controls Manager | E31: 46042 | F31: Active | G31: High | H31: 0.1 | I31: TRUE | J31: 27 | K31: 46042
A32: ACT-2026-0104 | B32: RSK-2026-0016 | C32: Run scope review workshop and log decisions in tracker | D32: Senior Manager, Risk Advisory | E32: 46058 | F32: In Review | G32: High | H32: 0.4 | I32: TRUE | J32: 10 | K32: 46058 | L32: Workshop scheduled, agenda created
A33: ACT-2026-0105 | B33: RSK-2026-0021 | C33: Draft public response template for closures and delays | D33: Customer Communications Manager | E33: 46063 | F33: Active | G33: Medium | H33: 0.5 | I33: TRUE | J33: 5 | K33: 46063 | L33: Template drafted, pending review
A34: ACT-2026-0106 | B34: RSK-2026-0022 | C34: Coordinate site walk-through and update safety signage checklist | D34: Safety Program Lead | E34: 46059 | F34: Active | G34: High | H34: 0.2 | I34: TRUE | J34: 9 | K34: 46059 | L34: Walk-through booked with ops
A35: ACT-2026-0107 | B35: RSK-2026-0023 | C35: Implement cleaning tracking log and weekly audit process | D35: Supervisor, Stations & Facilities | E35: 46065 | F35: Active | G35: Low | H35: 0 | I35: TRUE | J35: 3 | K35: 46065 | L35: Audit template created
A36: ACT-2026-0108 | B36: RSK-2026-0027 | C36: Prepare stakeholder update deck and mitigation timeline | D36: Senior Manager, Risk Advisory | E36: 46066 | F36: Active | G36: Medium | H36: 0.15 | I36: TRUE | J36: 2 | K36: 46066 | L36: Outline created, needs metrics
A37: {=SUBSTITUTE(INDEX(tblRisks[Risk_ID],ROW()-1),"RSK","ACT")}
A38: {=SUBSTITUTE(INDEX(tblRisks[Risk_ID],ROW()-1),"RSK","ACT")}
A39: {=SUBSTITUTE(INDEX(tblRisks[Risk_ID],ROW()-1),"RSK","ACT")}
A40: {=SUBSTITUTE(INDEX(tblRisks[Risk_ID],ROW()-1),"RSK","ACT")}
A41: {=SUBSTITUTE(INDEX(tblRisks[Risk_ID],ROW()-1),"RSK","ACT")}
A42: {=SUBSTITUTE(INDEX(tblRisks[Risk_ID],ROW()-1),"RSK","ACT")}
...

Sheet Dashboard
B2: Enterprise Risk Dashboard | G2: (Simulated Data)
C4: Filter: Status | J4: KPI Summary
G6: Total Risks | J6: Active Risks | M6: Outside Risk Appetite
G7: =Pivot_Data!$K$2 -> 27 | J7: =Pivot_Data!$K$3 -> 4 | M7: =Pivot_Data!$K$4 -> 1
G10: Open Actions | J10: Overdue Reviews | M10: Overdue Actions
G11: =Pivot_Data!$K$5 -> 19 | J11: =Pivot_Data!$K$6 -> 1 | M11: =Pivot_Data!$K$7 -> 8
B37: Top Ten Risks

Sheet Pivot_Data
A1: Pivot Tables | H1: KPI's
B2: Category | C2: Count | E2: Business Unit | F2: Count | I2: 1 | J2: Total Risks | K2: =COUNTA(tblRisks[Risk_ID]) -> 27
B3: Finance | C3: 4 | E3: Bus Ops | F3: 1 | I3: 2 | J3: Active Risks | K3: =COUNTIF(tblRisks[Status],"Active") -> 4
B4: IT | C4: 4 | E4: Capital Projects | F4: 2 | I4: 3 | J4: Outside Apetite | K4: =COUNTIF(tblRisks[Appetite_alignment],"Outside") -> 1
B5: Operational | C5: 4 | E5: Customer Experience | F5: 5 | I5: 4 | J5: Open Actions | K5: =COUNTIF(tblActions[Status],"Active")+COUNTIF(tblActions[Status],"In Review")+COUNTIF(tblActions[Status],"New") -> 19
B6: Projects | C6: 2 | E6: GO Ops | F6: 2 | I6: 5 | J6: Overdue Reviews | K6: =COUNTIFS(tblRisks[Status],"<>"&"Closed",tblRisks[Next_review_date],"<"&TODAY()) -> 1
B7: Reputation | C7: 7 | E7: Office of CRO | F7: 4 | I7: 6 | J7: Overdue Actions | K7: =COUNTIFS(tblActions[Status],"<>"&"Closed",tblActions[Due_Date],"<"&TODAY()) -> 8
B8: Safety | C8: 6 | E8: Grand Total | F8: 14
B9: Grand Total | C9: 27
